Workbook

Sheet README
A1: õpilased kellele on tehtud dummy andmetes mitu käskkirja rida (dubleerib ridu):
A2: S00023 | B2: mitme käskkirjaga õpilane
A3: S00041 | B3: mitme käskkirjaga õpilane
A4: S00058 | B4: mitme käskkirjaga õpilane
A5: S00019 | B5: mitme käskkirjaga õpilane
A6: S00027 | B6: mitme käskkirjaga õpilane
A7: S00054 | B7: mitme käskkirjaga õpilane
A8: S00045 | B8: mitme käskkirjaga õpilane
A9: S00047 | B9: mitme käskkirjaga õpilane
A13: 29.09.2025 mari | B13: dymmy data deklareemiste kuupäevad panin
B14: sügissem. | C14: 10.09.AASTA
B15: kevadsem. | C15: 10.02.AASTA
A17: 29.09.2025 mari | B17: kõik kes on katkestanud peab olema ka vähemalt üks käskkiri "eksmatrikuleerimine"
A19: 29.09.2025 mari | B19: opkood | C19: oppeaine | D19: EAP | E19: hindamisviis | F19: vana nimi
B20: Õppeaine kood | C20: Õppeaine nimetus | D20: Maht EAP | E20: Õppeaine hindamisviis | F20: uus; selline peaks olema ka kooli "õppeained csv" nimed
E26: õppeaasta
B27: 2020 | C27: 44105 | D27: 44469 | E27: 1
B28: 2021 | C28: 44470 | D28: 44834 | E28: 2
B29: 2022 | C29: 44835 | D29: 45199 | E29: 3
B30: 2023 | C30: 45200 | D30: 45565 | E30: 4
B31: 2024 | C31: 45566 | D31: 45930 | E31: 5
B32: 2025 | C32: 45931 | D32: 46295 | E32: 6

Sheet Tahvli andmed
E1: vastuvõtu kpv | F1: kui katkestas siis eksmatrikuleerimise käskkirja kuupäev | J1: immatrikuleerimise kpv-st aasta, millal see rühm alustas, kui rühma koodis ei kajastu aasta. | L1: võib muutuda ku näiteks akadeemilisel | N1: õpilase | Q1: kui suurem muudatus siis kood muutub, nt kui nominaalaeg muutub | T1: vastus: tudengi akadeemiline aasta. | W1: õppekava total-ist. | AG1: count õppeaine | AM1: vastus: kui sooritas ex/arvetust mitu korda,siis siin on lõpphinne. | AN1: Õppeaine tuleb päringu väljavõtus koodi ja nime kombinatsioonina, näiteks „6AA17/KF - Kliiniline farmakoloogia“. Eraldi ainult koodi valida ei ole võimalik. | AO1: Õppeaine =Deklareeritud õppeaine
A2: Sugu | B2: Külalisõppija | C2: Välisõppija | D2: Cum laude | E2: Immatrikuleeritud | F2: Lõpetanud | G2: Käskkirja kinnitamise kp | H2: Käskkirja liik | I2: Käskkirja põhjus | J2: Õpperühm | K2: Õppija staatus | L2: Nominaalaja lõpp | M2: Õppevorm | N2: Koormus | O2: Struktuuriüksus | P2: Õppekava | Q2: EHIS kood | R2: Õppetase | S2: Spetsialiseerumine | T2: Õppeaasta | U2: Rahastamine | V2: Õppekeel | W2: Õppekava täitmise protsent % | X2: Õppijal on erivajadus | Y2: Erivajaduse täpsustus | Z2: Õpipoisi ettevõte | AA2: Ainepunkte kokku | AB2: Ainepunkte perioodis | AC2: Kaalutud keskmine kokku | AD2: Kaalutud keskmine hinne perioodis | AE2: Keskmine kokku | AF2: Keskmine hinne perioodis | AG2: Võlad kokku | AH2: Võlad perioodis | AI2: Võlapunktid kokku EAP | AJ2: Võlapunktid perioodis EAP | AK2: Deklareeritud ainepunkte perioodis | AL2: VÕTA maht | AM2: Aktiivne sooritus aines | AN2: Õppeaine | AO2: Deklareeritud õppeaine | AP2: Deklaratsiooni kinnitus perioodis | AQ2: Eelnev haridus
A3: Mees | B3: Ei | C3: Ei | D3: Ei | E3: kuupäev | F3: kuupäev | G3: kuupäev | H3: Akadeemilise puhkuse katkestamine | I3: Lapsehoolduspuhkusel | J3: õpperühma tähis (ainult tähed või numbrid ja tähed) | K3: Akadeemilisel | L3: kuupäev | M3: Eksternõpe | N3: Määramata | O3: Meditsiinitehnilise hariduse keskus | P3: Assistant Pharmacist | Q3: 214475 | R3: 514 rakenduskõrgharidusõpe | S3: Intensiivõendus | T3: 1 | U3: SF programmist „PRÕM“ rahastatav õppekoht: õpipoisiõpe | V3: eesti keel | W3: protsent | X3: Ei | Y3: kirjeldus | Z3: asutuse nimi | AA3: arv | AB3: arv | AC3: arv | AD3: arv | AE3: arv | AF3: arv | AG3: arv | AH3: arv | AI3: arv | AJ3: arv | AK3: arv | AL3: arv | AM3: Arvestatud | AN3: õppeaine nimi | AO3: õppeaine nimi | AP3: kuupäev | AQ3: 310 üldkeskharidus
A4: Naine | B4: Jah | C4: Jah | D4: Jah | H4: Akadeemilisele puhkusele lubamine | I4: Omal soovil | K4: Katkestanud | M4: Päevaõpe | N4: Osakoormus | O4: Tervishariduse keskus | P4: Farmatseut | Q4: 1477 | R4: 614 magistriõpe (3+2) | S4: Kliiniline õendus | T4: 2 | U4: Üliõpilane ei hüvita õppekulusid: õpib täies mahus eestikeelsel õppekaval | V4: inglise keel | X4: Jah | AM4: Hea | AN4: 6AA17/KF - Kliiniline farmakoloogia | AQ4: 313 põhiharidust eeldav kutse- ja keskharidus
H5: Duplikaadi väljastamine | I5: Omal soovil - muud põhjused | K5: Lõpetanud | N5: Täiskoormus | O5: Õenduse õppetool | P5: Hambatehnik | Q5: 80166 | S5: Terviseõendus | T5: 3 | U5: Üliõpilane ei hüvita õppekulusid: on alla 7-a lapse või puudega lapse vanem või eestkostja | AM5: Kasin | AQ5: 314 põhiharidust eeldav keskeri-/tehnikumiharidus
H6: Eksmatrikuleerimine | I6: Tervislikel põhjustel | K6: Välisõppes | P6: Optometrist | Q6: 1479 | S6: Vaimse tervise õendus | T6: 4 | U6: Üliõpilane ei hüvita õppekulusid: vabastatud muudel põhjustel | AM6: Mittearvestatud | AN6: see veerg lüüa lahku deklareerimised tabelis | AQ6: 323 kutsekeskharidus põhihariduse baasil
H7: Eksternõppesse arvamine | I7: Õppetööle mitteilmumine | K7: Õpib | P7: Tegevusterapeut | Q7: 3311 | T7: 5 | U7: Üliõpilaselt nõutakse õppekulude hüvitamist puuduolevate ainepunktide eest | AM7: Mitteilmunud | AQ7: 411 kutsekeskharidusõpe
H8: Eksternõppest väljaarvamine | P8: Tervisedendus | Q8: 80997 | U8: Üliõpilaselt nõutakse õppekulude hüvitamist tasulisel õppekohal | AM8: Puudulik | AN8: õppeained tabelis on kood olemas | AQ8: 412 kutseõpe keskhariduse baasil
H9: Finantseerimisallika muutmine | P9: Terviseteadus | Q9: 194200 | AM9: Rahuldav | AQ9: 413 kutsekeskharidus keskhariduse baasil
H10: Immatrikuleerimine | P10: Õde | Q10: 1467 | AM10: Suurepärane | AQ10: 414 keskharidust eeldav keskeri-/tehnikumiharidus
H11: Käskkirja tühistamine | P11: Ämmaemand | Q11: 1470 | AM11: Väga hea | AQ11: 441 Neljanda taseme kutseõppe esmaõpe (kutsekeskharidusõpe)
H12: Lõpetamine | AQ12: 442 Neljanda taseme kutseõppe esmaõpe
H13: Muu | AQ13: 452 Viienda taseme kutseõppe esmaõpe
H14: Stipendiumi/õppetoetuse maksmise lõpetamine | AQ14: 503 integreeritud õpe
H15: Stipendiumi/õppetoetuse määramine | AQ15: 511 bakalaureuseõpe
H16: Tugimeetmete rakendamine | AQ16: 512 bakalaureuseõpe
H17: Tugimeetmete rakendamise lõpp | AQ17: 513 rakenduskõrgkooli ja ülikooli diplomiõpe
H18: Välisõpilaseks vormistamine | AQ18: 514 rakenduskõrgharidusõpe
H19: Välisõpingute katkestamine/varem lõpetamine | AQ19: 523 kutsekõrgharidus
H20: Õppekava vahetamine | AQ20: 614 magistriõpe (3+2)
H21: Õppekoormuse muutmine

Sheet Õppeained
A1: Õppeaine nimetus | B1: Õppeaine kood | C1: Maht EAP | D1: Õppeaine hindamisviis
A2: Accommodation and vergence dysfunction | B2: VAAVD-25 | C2: 4 | D2: arvestus (mitteeristav)
A3: Ajakirjaklubi | B3: 8VA18/AK | C3: 5 | D3: arvestus (mitteeristav)
A4: Akadeemiline kirjutamine | B4: 5PA13AK | C4: 2 | D4: arvestus (mitteeristav)
A5: Akrüülproteesid I | B5: 2DR113AP-1 | C5: 6 | D5: eksam (eristav hindamine)
A6: Akrüülproteesid I | B6: 2DR117/AP1 | C6: 8 | D6: eksam (eristav hindamine)
A7: Akrüülproteesid II | B7: 2DR113AP-2 | C7: 8 | D7: eksam (eristav hindamine)
A8: Akrüülproteesid II | B8: 2DR117/AP2 | C8: 8 | D8: eksam (eristav hindamine)
A9: Alusteadmised laste ja noorukite tegevusteraapiast | B9: 5TP17/ALNT | C9: 5 | D9: eksam (eristav hindamine)
A10: Alusteadmised laste ja noorukite tegevusteraapiast | B10: 5LNT13ALT | C10: 5 | D10: eksam (eristav hindamine)
A11: Alusteadmised laste ja noorukite tegevusteraapiast | B11: 5TP20/ALNT | C11: 5 | D11: eksam (eristav hindamine)
A12: Analüütiline keemia | B12: 1KE09/AK | C12: 6 | D12: hindeline arvestus (eristav hindamine)
A13: Analüütiline keemia | B13: 1iC19/AC | C13: 4 | D13: eksam (eristav hindamine)
... A1088: Ülevaade hammaste morfoloogiast | B1088: VA17/ÜHM | C1088: 5 | D1088: arvestus (mitteeristav)

Sheet opained_pivot
I1: Õppeaine hindamisviis
A2: Õppeaine nimetus | B2: (All) | I2: arvestus (mitteeristav)
A3: Maht EAP | B3: (All) | I3: eksam (eristav hindamine)
I4: hindeline arvestus (eristav hindamine)
A5: Count of Õppeaine kood
A6: Õppeaine hindamisviis | B6: Total
A7: arvestus (mitteeristav) | B7: 439
A8: eksam (eristav hindamine) | B8: 533
A9: hindeline arvestus (eristav hindamine) | B9: 115
A10: (blank)
A11: Grand Total | B11: 1087
I19: Kaalutud keskmine hinne = | P19: Kaalutud keskmine hinne =
I20: VAR Hinne_EAP = | P20: VAR Hinne_EAP =
I21: SUMX ( | P21: SUMX (
I22: FILTER ( | P22: FILTER (
I23: deklareerimised, | P23: deklareerimised,
I24: CONTAINSSTRING ( RELATED ( 'oppeained_katsetamiseks'[hindamisviis] ), "eristav" ) | P24: NOT CONTAINSSTRING ( RELATED (oppeained_katsetamiseks[Õppeaine hindamisviis]), "mitteeristav" )
I25: ), | P25: ),
I26: deklareerimised[sooritus_arvuna] * RELATED ( 'oppeained_katsetamiseks'[EAP] ) | P26: deklareerimised[sooritus_arvuna] * RELATED (oppeained_katsetamiseks[Maht EAP])
I27: ) | P27: )
I28: VAR Kokku_EAP = | P28: VAR Kokku_EAP =
I29: SUMX ( | P29: SUMX (
I30: FILTER ( | P30: FILTER (
... I82: DIVIDE ( Hinne_EAP, Kokku_EAP ) | P82: DIVIDE ( Hinne_EAP, Kokku_EAP )

Sheet dummy_oppeained
A1: Õppeaine kood | B1: Õppeaine nimetus | C1: Maht EAP | D1: Õppeaine hindamisviis
A2: 1 | B2: õppeaine1 | C2: 3 | D2: mitteeristav
A3: 2 | B3: õppeaine2 | C3: 6 | D3: eristav
A4: 3 | B4: õppeaine3 | C4: 3 | D4: mitteeristav
A5: 4 | B5: õppeaine4 | C5: 2 | D5: mitteeristav
A6: 5 | B6: õppeaine5 | C6: 2 | D6: mitteeristav
A7: 6 | B7: õppeaine6 | C7: 3 | D7: mitteeristav
A8: 7 | B8: õppeaine7 | C8: 3 | D8: mitteeristav
A9: 8 | B9: õppeaine8 | C9: 6 | D9: eristav
A10: 9 | B10: õppeaine9 | C10: 8 | D10: eristav
A11: 10 | B11: õppeaine10 | C11: 9 | D11: eristav
A12: 11 | B12: õppeaine11 | C12: 10 | D12: eristav
A13: 12 | B13: õppeaine12 | C13: 5 | D13: eristav
... A444: 443 | B444: õppeaine443 | C444: 8 | D444: eristav

Sheet dummy_data
A1: matrikli_nr | B1: eesnimi | C1: perenimi | D1: täisnimi | E1: isikukood | F1: Sugu | G1: Eelnev haridus | H1: Külalisõppija | I1: Välisõppija | J1: Cum laude | K1: Immatrikuleeritud | L1: Lõpetanud | M1: Käskkirja kinnitamise kp | N1: Käskkirja liik | O1: Käskkirja põhjus | P1: Õpperühm | Q1: Õppija staatus | R1: Nominaalaja lõpp | S1: Õppevorm | T1: Koormus | U1: Struktuuriüksus | V1: Õppekava | W1: Õppekava EHIS kood | X1: Õppetase | Y1: Spetsialiseerumine | Z1: Õppeaasta | AA1: Rahastamine | AB1: Õppekeel | AC1: Õppekava täitmise protsent % | AD1: Õppijal on erivajadus | AE1: Erivajaduse täpsustus | AF1: Õpipoisi ettevõte | AG1: Ainepunkte kokku | AH1: Ainepunkte perioodis | AI1: Kaalutud keskmine kokku | AJ1: Kaalutud keskmine hinne perioodis | AK1: Keskmine kokku | AL1: Keskmine hinne perioodis | AM1: Võlad kokku | AN1: Võlad perioodis | AO1: Võlapunktid kokku EAP | AP1: Võlapunktid perioodis EAP | AQ1: Deklareeritud ainepunkte perioodis | AR1: VÕTA maht | AS1: Aktiivne sooritus aines | AT1: Õppeaine | AU1: Deklareeritud õppeaine | AV1: Deklaratsiooni kinnitus perioodis | AW1: Õppekava Nominaalaeg (a) | AX1: EAP | AY1: hindamisviis | AZ1: Sooritus_arvuna | BA1: EAP_sooritus_eristav | BB1: EAP_eristav | BC1: abiveerg | BD1: row_count | BE1: v
A2: S00001 | B2: Pille | C2: Tamm | D2: Pille Tamm | E2: 51206259631 | F2: Naine | G2: 323 kutsekeskharidus põhihariduse baasil | H2: Jah | I2: Jah | J2: Jah | K2: 44440 | L2: 45835 | M2: 44502 | N2: Eksmatrikuleerimine | O2: Tervislikel põhjustel | P2: 21sügis_TT | Q2: Katkestanud | R2: 44531 | S2: Eksternõpe | T2: Osakoormus | U2: Tervishariduse keskus | V2: Tegevusterapeut | W2: 3311 | X2: 514 rakenduskõrgharidusõpe | Y2: NULL | Z2: 1 | AA2: SF programmist „PRÕM“ rahastatav õppekoht: õpipoisiõpe | AB2: eesti keel | AC2: 0.5 | AD2: Jah | AE2: liikumispuue | AF2: NULL | AG2: 185 | AH2: 47 | AI2: 3.1 | AJ2: 3.3 | AK2: 3.3 | AL2: 3.7 | AM2: 4 | AN2: 2 | AO2: 4 | AP2: 4 | AQ2: 56 | AR2: 4 | AS2: Puudulik | AT2: õppeaine22 | AU2: õppeaine22 | AV2: 44449 | AW2: 4 | AX2: =VLOOKUP(dummy_data!$AU2,dummy_oppeained!B:C,2,0) -> 6 | AY2: =VLOOKUP(AT2,dummy_oppeained!B:D,3,0) -> eristav | AZ2: =VLOOKUP(AS:AS,hinded_abi!B:D,3,0) -> 0 | BA2: =IF(AY2="eristav",AX2*AZ2," ") -> 0 | BB2: =IF(AY2="eristav",AX2,0) -> 6 | BC2: =_xlfn.CONCAT(A2,"_",E2,"_",AT2,"_",AV2) -> S00001_51206259631_õppeaine22_44449 | BD2: =COUNTIF($BC$2:BC2, BC2) -> 1
A3: S00001 | B3: Pille | C3: Tamm | D3: Pille Tamm | E3: 51206259631 | F3: Naine | G3: 323 kutsekeskharidus põhihariduse baasil | H3: Jah | I3: Jah | J3: Jah | K3: 44440 | L3: 45835 | M3: 44502 | N3: Eksmatrikuleerimine | O3: Tervislikel põhjustel | P3: 21sügis_TT | Q3: Katkestanud | R3: 44531 | S3: Eksternõpe | T3: Osakoormus | U3: Tervishariduse keskus | V3: Tegevusterapeut | W3: 3311 | X3: 514 rakenduskõrgharidusõpe | Y3: NULL | Z3: 1 | AA3: SF programmist „PRÕM“ rahastatav õppekoht: õpipoisiõpe | AB3: eesti keel | AC3: 0.5 | AD3: Jah | AE3: liikumispuue | AF3: NULL | AG3: 185 | AH3: 47 | AI3: 3.1 | AJ3: 3.3 | AK3: 3.3 | AL3: 3.7 | AM3: 4 | AN3: 2 | AO3: 4 | AP3: 4 | AQ3: 56 | AR3: 4 | AS3: Suurepärane | AT3: õppeaine2 | AU3: õppeaine2 | AV3: 44449 | AW3: 4 | AX3: =VLOOKUP(dummy_data!$AU3,dummy_oppeained!B:C,2,0) -> 6 | AY3: =VLOOKUP(AT3,dummy_oppeained!B:D,3,0) -> eristav | AZ3: =VLOOKUP(AS:AS,hinded_abi!B:D,3,0) -> 5 | BA3: =IF(AY3="eristav",AX3*AZ3," ") -> 30 | BB3: =IF(AY3="eristav",AX3,0) -> 6 | BC3: =_xlfn.CONCAT(A3,"_",E3,"_",AT3,"_",AV3) -> S00001_51206259631_õppeaine2_44449 | BD3: =COUNTIF($BC$2:BC3, BC3) -> 1
A4: S00001 | B4: Pille | C4: Tamm | D4: Pille Tamm | E4: 51206259631 | F4: Naine | G4: 323 kutsekeskharidus põhihariduse baasil | H4: Jah | I4: Jah | J4: Jah | K4: 44440 | L4: 45835 | M4: 44502 | N4: Eksmatrikuleerimine | O4: Tervislikel põhjustel | P4: 21sügis_TT | Q4: Katkestanud | R4: 44531 | S4: Eksternõpe | T4: Osakoormus | U4: Tervishariduse keskus | V4: Tegevusterapeut | W4: 3311 | X4: 514 rakenduskõrgharidusõpe | Y4: NULL | Z4: 1 | AA4: SF programmist „PRÕM“ rahastatav õppekoht: õpipoisiõpe | AB4: eesti keel | AC4: 0.5 | AD4: Jah | AE4: liikumispuue | AF4: NULL | AG4: 185 | AH4: 47 | AI4: 3.1 | AJ4: 3.3 | AK4: 3.3 | AL4: 3.7 | AM4: 4 | AN4: 2 | AO4: 4 | AP4: 4 | AQ4: 56 | AR4: 4 | AS4: Arvestatud | AT4: õppeaine85 | AU4: õppeaine85 | AV4: 44449 | AW4: 4 | AX4: =VLOOKUP(dummy_data!$AU4,dummy_oppeained!B:C,2,0) -> 3 | AY4: =VLOOKUP(AT4,dummy_oppeained!B:D,3,0) -> mitteeristav | AZ4: =VLOOKUP(AS:AS,hinded_abi!B:D,3,0) -> NULL | BA4: =IF(AY4="eristav",AX4*AZ4," ") | BB4: =IF(AY4="eristav",AX4,0) -> 0 | BC4: =_xlfn.CONCAT(A4,"_",E4,"_",AT4,"_",AV4) -> S00001_51206259631_õppeaine85_44449 | BD4: =COUNTIF($BC$2:BC4, BC4) -> 1
A5: S00001 | B5: Pille | C5: Tamm | D5: Pille Tamm | E5: 51206259631 | F5: Naine | G5: 323 kutsekeskharidus põhihariduse baasil | H5: Jah | I5: Jah | J5: Jah | K5: 44440 | L5: 45835 | M5: 44502 | N5: Eksmatrikuleerimine | O5: Tervislikel põhjustel | P5: 21sügis_TT | Q5: Katkestanud | R5: 44531 | S5: Eksternõpe | T5: Osakoormus | U5: Tervishariduse keskus | V5: Tegevusterapeut | W5: 3311 | X5: 514 rakenduskõrgharidusõpe | Y5: NULL | Z5: 1 | AA5: SF programmist „PRÕM“ rahastatav õppekoht: õpipoisiõpe | AB5: eesti keel | AC5: 0.5 | AD5: Jah | AE5: liikumispuue | AF5: NULL | AG5: 185 | AH5: 47 | AI5: 3.1 | AJ5: 3.3 | AK5: 3.3 | AL5: 3.7 | AM5: 4 | AN5: 2 | AO5: 4 | AP5: 4 | AQ5: 56 | AR5: 4 | AS5: Arvestatud | AT5: õppeaine29 | AU5: õppeaine29 | AV5: 44449 | AW5: 4 | AX5: =VLOOKUP(dummy_data!$AU5,dummy_oppeained!B:C,2,0) -> 3 | AY5: =VLOOKUP(AT5,dummy_oppeained!B:D,3,0) -> mitteeristav | AZ5: =VLOOKUP(AS:AS,hinded_abi!B:D,3,0) -> NULL | BA5: =IF(AY5="eristav",AX5*AZ5," ") | BB5: =IF(AY5="eristav",AX5,0) -> 0 | BC5: =_xlfn.CONCAT(A5,"_",E5,"_",AT5,"_",AV5) -> S00001_51206259631_õppeaine29_44449 | BD5: =COUNTIF($BC$2:BC5, BC5) -> 1
A6: S00001 | B6: Pille | C6: Tamm | D6: Pille Tamm | E6: 51206259631 | F6: Naine | G6: 323 kutsekeskharidus põhihariduse baasil | H6: Jah | I6: Jah | J6: Jah | K6: 44440 | L6: 45835 | M6: 44502 | N6: Eksmatrikuleerimine | O6: Tervislikel põhjustel | P6: 21sügis_TT | Q6: Katkestanud | R6: 44531 | S6: Eksternõpe | T6: Osakoormus | U6: Tervishariduse keskus | V6: Tegevusterapeut | W6: 3311 | X6: 514 rakenduskõrgharidusõpe | Y6: NULL | Z6: 1 | AA6: SF programmist „PRÕM“ rahastatav õppekoht: õpipoisiõpe | AB6: eesti keel | AC6: 0.5 | AD6: Jah | AE6: liikumispuue | AF6: NULL | AG6: 185 | AH6: 47 | AI6: 3.1 | AJ6: 3.3 | AK6: 3.3 | AL6: 3.7 | AM6: 4 | AN6: 2 | AO6: 4 | AP6: 4 | AQ6: 56 | AR6: 4 | AS6: Puudulik | AT6: õppeaine24 | AU6: õppeaine24 | AV6: 44449 | AW6: 4 | AX6: =VLOOKUP(dummy_data!$AU6,dummy_oppeained!B:C,2,0) -> 9 | AY6: =VLOOKUP(AT6,dummy_oppeained!B:D,3,0) -> eristav | AZ6: =VLOOKUP(AS:AS,hinded_abi!B:D,3,0) -> 0 | BA6: =IF(AY6="eristav",AX6*AZ6," ") -> 0 | BB6: =IF(AY6="eristav",AX6,0) -> 9 | BC6: =_xlfn.CONCAT(A6,"_",E6,"_",AT6,"_",AV6) -> S00001_51206259631_õppeaine24_44449 | BD6: =COUNTIF($BC$2:BC6, BC6) -> 1
A7: S00001 | B7: Pille | C7: Tamm | D7: Pille Tamm | E7: 51206259631 | F7: Naine | G7: 323 kutsekeskharidus põhihariduse baasil | H7: Jah | I7: Jah | J7: Jah | K7: 44440 | L7: 45835 | M7: 44502 | N7: Eksmatrikuleerimine | O7: Tervislikel põhjustel | P7: 21sügis_TT | Q7: Katkestanud | R7: 44531 | S7: Eksternõpe | T7: Osakoormus | U7: Tervishariduse keskus | V7: Tegevusterapeut | W7: 3311 | X7: 514 rakenduskõrgharidusõpe | Y7: NULL | Z7: 1 | AA7: SF programmist „PRÕM“ rahastatav õppekoht: õpipoisiõpe | AB7: eesti keel | AC7: 0.5 | AD7: Jah | AE7: liikumispuue | AF7: NULL | AG7: 185 | AH7: 47 | AI7: 3.1 | AJ7: 3.3 | AK7: 3.3 | AL7: 3.7 | AM7: 4 | AN7: 2 | AO7: 4 | AP7: 4 | AQ7: 56 | AR7: 4 | AS7: Mittearvestatud | AT7: õppeaine59 | AU7: õppeaine59 | AV7: 44449 | AW7: 4 | AX7: =VLOOKUP(dummy_data!$AU7,dummy_oppeained!B:C,2,0) -> 3 | AY7: =VLOOKUP(AT7,dummy_oppeained!B:D,3,0) -> mitteeristav | AZ7: =VLOOKUP(AS:AS,hinded_abi!B:D,3,0) -> NULL | BA7: =IF(AY7="eristav",AX7*AZ7," ") | BB7: =IF(AY7="eristav",AX7,0) -> 0 | BC7: =_xlfn.CONCAT(A7,"_",E7,"_",AT7,"_",AV7) -> S00001_51206259631_õppeaine59_44449 | BD7: =COUNTIF($BC$2:BC7, BC7) -> 1
A8: S00001 | B8: Pille | C8: Tamm | D8: Pille Tamm | E8: 51206259631 | F8: Naine | G8: 323 kutsekeskharidus põhihariduse baasil | H8: Jah | I8: Jah | J8: Jah | K8: 44440 | L8: 45835 | M8: 44502 | N8: Eksmatrikuleerimine | O8: Tervislikel põhjustel | P8: 21sügis_TT | Q8: Katkestanud | R8: 44531 | S8: Eksternõpe | T8: Osakoormus | U8: Tervishariduse keskus | V8: Tegevusterapeut | W8: 3311 | X8: 514 rakenduskõrgharidusõpe | Y8: NULL | Z8: 1 | AA8: SF programmist „PRÕM“ rahastatav õppekoht: õpipoisiõpe | AB8: eesti keel | AC8: 0.5 | AD8: Jah | AE8: liikumispuue | AF8: NULL | AG8: 185 | AH8: 47 | AI8: 3.1 | AJ8: 3.3 | AK8: 3.3 | AL8: 3.7 | AM8: 4 | AN8: 2 | AO8: 4 | AP8: 4 | AQ8: 56 | AR8: 4 | AS8: Hea | AT8: õppeaine84 | AU8: õppeaine84 | AV8: 44449 | AW8: 4 | AX8: =VLOOKUP(dummy_data!$AU8,dummy_oppeained!B:C,2,0) -> 6 | AY8: =VLOOKUP(AT8,dummy_oppeained!B:D,3,0) -> eristav | AZ8: =VLOOKUP(AS:AS,hinded_abi!B:D,3,0) -> 3 | BA8: =IF(AY8="eristav",AX8*AZ8," ") -> 18 | BB8: =IF(AY8="eristav",AX8,0) -> 6 | BC8: =_xlfn.CONCAT(A8,"_",E8,"_",AT8,"_",AV8) -> S00001_51206259631_õppeaine84_44449 | BD8: =COUNTIF($BC$2:BC8, BC8) -> 1
A9: S00001 | B9: Pille | C9: Tamm | D9: Pille Tamm | E9: 51206259631 | F9: Naine | G9: 323 kutsekeskharidus põhihariduse baasil | H9: Jah | I9: Jah | J9: Jah | K9: 44440 | L9: 45835 | M9: 44502 | N9: Eksmatrikuleerimine | O9: Tervislikel põhjustel | P9: 21sügis_TT | Q9: Katkestanud | R9: 44531 | S9: Eksternõpe | T9: Osakoormus | U9: Tervishariduse keskus | V9: Tegevusterapeut | W9: 3311 | X9: 514 rakenduskõrgharidusõpe | Y9: NULL | Z9: 1 | AA9: SF programmist „PRÕM“ rahastatav õppekoht: õpipoisiõpe | AB9: eesti keel | AC9: 0.5 | AD9: Jah | AE9: liikumispuue | AF9: NULL | AG9: 185 | AH9: 47 | AI9: 3.1 | AJ9: 3.3 | AK9: 3.3 | AL9: 3.7 | AM9: 4 | AN9: 2 | AO9: 4 | AP9: 4 | AQ9: 56 | AR9: 4 | AS9: Mittearvestatud | AT9: õppeaine76 | AU9: õppeaine76 | AV9: 44449 | AW9: 4 | AX9: =VLOOKUP(dummy_data!$AU9,dummy_oppeained!B:C,2,0) -> 3 | AY9: =VLOOKUP(AT9,dummy_oppeained!B:D,3,0) -> mitteeristav | AZ9: =VLOOKUP(AS:AS,hinded_abi!B:D,3,0) -> NULL | BA9: =IF(AY9="eristav",AX9*AZ9," ") | BB9: =IF(AY9="eristav",AX9,0) -> 0 | BC9: =_xlfn.CONCAT(A9,"_",E9,"_",AT9,"_",AV9) -> S00001_51206259631_õppeaine76_44449 | BD9: =COUNTIF($BC$2:BC9, BC9) -> 1
A10: S00001 | B10: Pille | C10: Tamm | D10: Pille Tamm | E10: 51206259631 | F10: Naine | G10: 323 kutsekeskharidus põhihariduse baasil | H10: Jah | I10: Jah | J10: Jah | K10: 44440 | L10: 45835 | M10: 44502 | N10: Eksmatrikuleerimine | O10: Tervislikel põhjustel | P10: 21sügis_TT | Q10: Katkestanud | R10: 44531 | S10: Eksternõpe | T10: Osakoormus | U10: Tervishariduse keskus | V10: Tegevusterapeut | W10: 3311 | X10: 514 rakenduskõrgharidusõpe | Y10: NULL | Z10: 1 | AA10: SF programmist „PRÕM“ rahastatav õppekoht: õpipoisiõpe | AB10: eesti keel | AC10: 0.5 | AD10: Jah | AE10: liikumispuue | AF10: NULL | AG10: 185 | AH10: 47 | AI10: 3.1 | AJ10: 3.3 | AK10: 3.3 | AL10: 3.7 | AM10: 4 | AN10: 2 | AO10: 4 | AP10: 4 | AQ10: 56 | AR10: 4 | AS10: Hea | AT10: õppeaine79 | AU10: õppeaine79 | AV10: 44449 | AW10: 4 | AX10: =VLOOKUP(dummy_data!$AU10,dummy_oppeained!B:C,2,0) -> 8 | AY10: =VLOOKUP(AT10,dummy_oppeained!B:D,3,0) -> eristav | AZ10: =VLOOKUP(AS:AS,hinded_abi!B:D,3,0) -> 3 | BA10: =IF(AY10="eristav",AX10*AZ10," ") -> 24 | BB10: =IF(AY10="eristav",AX10,0) -> 8 | BC10: =_xlfn.CONCAT(A10,"_",E10,"_",AT10,"_",AV10) -> S00001_51206259631_õppeaine79_44449 | BD10: =COUNTIF($BC$2:BC10, BC10) -> 1
A11: S00001 | B11: Pille | C11: Tamm | D11: Pille Tamm | E11: 51206259631 | F11: Naine | G11: 323 kutsekeskharidus põhihariduse baasil | H11: Jah | I11: Jah | J11: Jah | K11: 44440 | L11: 45835 | M11: 44502 | N11: Eksmatrikuleerimine | O11: Tervislikel põhjustel | P11: 21sügis_TT | Q11: Katkestanud | R11: 44531 | S11: Eksternõpe | T11: Osakoormus | U11: Tervishariduse keskus | V11: Tegevusterapeut | W11: 3311 | X11: 514 rakenduskõrgharidusõpe | Y11: NULL | Z11: 2 | AA11: SF programmist „PRÕM“ rahastatav õppekoht: õpipoisiõpe | AB11: eesti keel | AC11: 0.9 | AD11: Jah | AE11: liikumispuue | AF11: NULL | AG11: 185 | AH11: 30 | AI11: 3.1 | AJ11: 4.4 | AK11: 3.3 | AL11: 3.3 | AM11: 4 | AN11: 1 | AO11: 4 | AP11: 10 | AQ11: 43 | AR11: 4 | AS11: Väga hea | AT11: õppeaine67 | AU11: õppeaine67 | AV11: 44449 | AW11: 4 | AX11: =VLOOKUP(dummy_data!$AU11,dummy_oppeained!B:C,2,0) -> 5 | AY11: =VLOOKUP(AT11,dummy_oppeained!B:D,3,0) -> eristav | AZ11: =VLOOKUP(AS:AS,hinded_abi!B:D,3,0) -> 4 | BA11: =IF(AY11="eristav",AX11*AZ11," ") -> 20 | BB11: =IF(AY11="eristav",AX11,0) -> 5 | BC11: =_xlfn.CONCAT(A11,"_",E11,"_",AT11,"_",AV11) -> S00001_51206259631_õppeaine67_44449 | BD11: =COUNTIF($BC$2:BC11, BC11) -> 1
A12: S00001 | B12: Pille | C12: Tamm | D12: Pille Tamm | E12: 51206259631 | F12: Naine | G12: 323 kutsekeskharidus põhihariduse baasil | H12: Jah | I12: Jah | J12: Jah | K12: 44440 | L12: 45835 | M12: 44502 | N12: Eksmatrikuleerimine | O12: Tervislikel põhjustel | P12: 21sügis_TT | Q12: Katkestanud | R12: 44531 | S12: Eksternõpe | T12: Osakoormus | U12: Tervishariduse keskus | V12: Tegevusterapeut | W12: 3311 | X12: 514 rakenduskõrgharidusõpe | Y12: NULL | Z12: 2 | AA12: SF programmist „PRÕM“ rahastatav õppekoht: õpipoisiõpe | AB12: eesti keel | AC12: 0.9 | AD12: Jah | AE12: liikumispuue | AF12: NULL | AG12: 185 | AH12: 30 | AI12: 3.1 | AJ12: 4.4 | AK12: 3.3 | AL12: 3.3 | AM12: 4 | AN12: 1 | AO12: 4 | AP12: 10 | AQ12: 43 | AR12: 4 | AS12: Hea | AT12: õppeaine39 | AU12: õppeaine39 | AV12: 44449 | AW12: 4 | AX12: =VLOOKUP(dummy_data!$AU12,dummy_oppeained!B:C,2,0) -> 5 | AY12: =VLOOKUP(AT12,dummy_oppeained!B:D,3,0) -> eristav | AZ12: =VLOOKUP(AS:AS,hinded_abi!B:D,3,0) -> 3 | BA12: =IF(AY12="eristav",AX12*AZ12," ") -> 15 | BB12: =IF(AY12="eristav",AX12,0) -> 5 | BC12: =_xlfn.CONCAT(A12,"_",E12,"_",AT12,"_",AV12) -> S00001_51206259631_õppeaine39_44449 | BD12: =COUNTIF($BC$2:BC12, BC12) -> 1
A13: S00001 | B13: Pille | C13: Tamm | D13: Pille Tamm | E13: 51206259631 | F13: Naine | G13: 323 kutsekeskharidus põhihariduse baasil | H13: Jah | I13: Jah | J13: Jah | K13: 44440 | L13: 45835 | M13: 44502 | N13: Eksmatrikuleerimine | O13: Tervislikel põhjustel | P13: 21sügis_TT | Q13: Katkestanud | R13: 44531 | S13: Eksternõpe | T13: Osakoormus | U13: Tervishariduse keskus | V13: Tegevusterapeut | W13: 3311 | X13: 514 rakenduskõrgharidusõpe | Y13: NULL | Z13: 2 | AA13: SF programmist „PRÕM“ rahastatav õppekoht: õpipoisiõpe | AB13: eesti keel | AC13: 0.9 | AD13: Jah | AE13: liikumispuue | AF13: NULL | AG13: 185 | AH13: 30 | AI13: 3.1 | AJ13: 4.4 | AK13: 3.3 | AL13: 3.3 | AM13: 4 | AN13: 1 | AO13: 4 | AP13: 10 | AQ13: 43 | AR13: 4 | AS13: Arvestatud | AT13: õppeaine3 | AU13: õppeaine3 | AV13: 44449 | AW13: 4 | AX13: =VLOOKUP(dummy_data!$AU13,dummy_oppeained!B:C,2,0) -> 3 | AY13: =VLOOKUP(AT13,dummy_oppeained!B:D,3,0) -> mitteeristav | AZ13: =VLOOKUP(AS:AS,hinded_abi!B:D,3,0) -> NULL | BA13: =IF(AY13="eristav",AX13*AZ13," ") | BB13: =IF(AY13="eristav",AX13,0) -> 0 | BC13: =_xlfn.CONCAT(A13,"_",E13,"_",AT13,"_",AV13) -> S00001_51206259631_õppeaine3_44449 | BD13: =COUNTIF($BC$2:BC13, BC13) -> 1
... A27: S00001 | B27: Pille | C27: Tamm | D27: Pille Tamm | E27: 51206259631 | F27: Naine | G27: 323 kutsekeskharidus põhihariduse baasil | H27: Jah | I27: Jah | J27: Jah | K27: 44440 | L27: 45835 | M27: 44502 | N27: Eksmatrikuleerimine | O27: Tervislikel põhjustel | P27: 21sügis_TT | Q27: Katkestanud | R27: 44531 | S27: Eksternõpe | T27: Osakoormus | U27: Tervishariduse keskus | V27: Tegevusterapeut | W27: 3311 | X27: 514 rakenduskõrgharidusõpe | Y27: NULL | Z27: 4 | AA27: SF programmist „PRÕM“ rahastatav õppekoht: õpipoisiõpe | AB27: eesti keel | AC27: 0.6 | AD27: Jah | AE27: liikumispuue | AF27: NULL | AG27: 185 | AH27: 29 | AI27: 3.1 | AJ27: 4.4 | AK27: 3.3 | AL27: 3.9 | AM27: 4 | AN27: 3 | AO27: 4 | AP27: 3 | AQ27: 27 | AR27: 4 | AS27: Puudulik | AT27: õppeaine98 | AU27: õppeaine98 | AV27: 44449 | AW27: 4 | AX27: =VLOOKUP(dummy_data!$AU27,dummy_oppeained!B:C,2,0) -> 6 | AY27: =VLOOKUP(AT27,dummy_oppeained!B:D,3,0) -> eristav | AZ27: =VLOOKUP(AS:AS,hinded_abi!B:D,3,0) -> 0 | BA27: =IF(AY27="eristav",AX27*AZ27," ") -> 0 | BB27: =IF(AY27="eristav",AX27,0) -> 6 | BC27: =_xlfn.CONCAT(A27,"_",E27,"_",AT27,"_",AV27) -> S00001_51206259631_õppeaine98_44449 | BD27: =COUNTIF($BC$2:BC27, BC27) -> 1
A28: S00002 | B28: Anna | C28: Pärn | D28: Anna Pärn | E28: 53609056192 | F28: Naine | G28: 412 kutseõpe keskhariduse baasil | H28: Jah | I28: Ei | J28: Jah | K28: 44440 | L28: NULL | M28: 44504 | N28: Tugimeetmete rakendamine | O28: NULL | P28: 21sügis_TT | Q28: Akadeemilisel | R28: 44123 | S28: Päevaõpe | T28: Täiskoormus | U28: Tervishariduse keskus | V28: Tegevusterapeut | W28: 3311 | X28: 514 rakenduskõrgharidusõpe | Y28: NULL | Z28: 1 | AA28: Üliõpilaselt nõutakse õppekulude hüvitamist tasulisel õppekohal | AB28: eesti keel | AC28: 0.2 | AD28: Jah | AE28: liikumispuue | AF28: NULL | AG28: 184 | AH28: 33 | AI28: 4.9 | AJ28: 4.0 | AK28: 5.0 | AL28: 4.9 | AM28: 3 | AN28: 2 | AO28: 17 | AP28: 2 | AQ28: 48 | AR28: 9 | AS28: Arvestatud | AT28: õppeaine60 | AU28: õppeaine60 | AV28: 45698 | AW28: 4 | AX28: =VLOOKUP(dummy_data!$AU28,dummy_oppeained!B:C,2,0) -> 2 | AY28: =VLOOKUP(AT28,dummy_oppeained!B:D,3,0) -> mitteeristav | AZ28: =VLOOKUP(AS:AS,hinded_abi!B:D,3,0) -> NULL | BA28: =IF(AY28="eristav",AX28*AZ28," ") | BB28: =IF(AY28="eristav",AX28,0) -> 0 | BC28: =_xlfn.CONCAT(A28,"_",E28,"_",AT28,"_",AV28) -> S00002_53609056192_õppeaine60_45698 | BD28: =COUNTIF($BC$2:BC28, BC28) -> 1
A29: S00002 | B29: Anna | C29: Pärn | D29: Anna Pärn | E29: 53609056192 | F29: Naine | G29: 412 kutseõpe keskhariduse baasil | H29: Jah | I29: Ei | J29: Jah | K29: 44440 | L29: NULL | M29: 44504 | N29: Tugimeetmete rakendamine | O29: NULL | P29: 21sügis_TT | Q29: Akadeemilisel | R29: 44123 | S29: Päevaõpe | T29: Täiskoormus | U29: Tervishariduse keskus | V29: Tegevusterapeut | W29: 3311 | X29: 514 rakenduskõrgharidusõpe | Y29: NULL | Z29: 1 | AA29: Üliõpilaselt nõutakse õppekulude hüvitamist tasulisel õppekohal | AB29: eesti keel | AC29: 0.2 | AD29: Jah | AE29: liikumispuue | AF29: NULL | AG29: 184 | AH29: 33 | AI29: 4.9 | AJ29: 4.0 | AK29: 5.0 | AL29: 4.9 | AM29: 3 | AN29: 2 | AO29: 17 | AP29: 2 | AQ29: 48 | AR29: 9 | AS29: Puudulik | AT29: õppeaine13 | AU29: õppeaine13 | AV29: 45332 | AW29: 4 | AX29: =VLOOKUP(dummy_data!$AU29,dummy_oppeained!B:C,2,0) -> 6 | AY29: =VLOOKUP(AT29,dummy_oppeained!B:D,3,0) -> eristav | AZ29: =VLOOKUP(AS:AS,hinded_abi!B:D,3,0) -> 0 | BA29: =IF(AY29="eristav",AX29*AZ29," ") -> 0 | BB29: =IF(AY29="eristav",AX29,0) -> 6 | BC29: =_xlfn.CONCAT(A29,"_",E29,"_",AT29,"_",AV29) -> S00002_53609056192_õppeaine13_45332 | BD29: =COUNTIF($BC$2:BC29, BC29) -> 1
A30: S00002 | B30: Anna | C30: Pärn | D30: Anna Pärn | E30: 53609056192 | F30: Naine | G30: 412 kutseõpe keskhariduse baasil | H30: Jah | I30: Ei | J30: Jah | K30: 44440 | L30: NULL | M30: 44504 | N30: Tugimeetmete rakendamine | O30: NULL | P30: 21sügis_TT | Q30: Akadeemilisel | R30: 44123 | S30: Päevaõpe | T30: Täiskoormus | U30: Tervishariduse keskus | V30: Tegevusterapeut | W30: 3311 | X30: 514 rakenduskõrgharidusõpe | Y30: NULL | Z30: 1 | AA30: Üliõpilaselt nõutakse õppekulude hüvitamist tasulisel õppekohal | AB30: eesti keel | AC30: 0.2 | AD30: Jah | AE30: liikumispuue | AF30: NULL | AG30: 184 | AH30: 33 | AI30: 4.9 | AJ30: 4.0 | AK30: 5.0 | AL30: 4.9 | AM30: 3 | AN30: 2 | AO30: 17 | AP30: 2 | AQ30: 48 | AR30: 9 | AS30: Arvestatud | AT30: õppeaine46 | AU30: õppeaine46 | AV30: 44237 | AW30: 4 | AX30: =VLOOKUP(dummy_data!$AU30,dummy_oppeained!B:C,2,0) -> 2 | AY30: =VLOOKUP(AT30,dummy_oppeained!B:D,3,0) -> mitteeristav | AZ30: =VLOOKUP(AS:AS,hinded_abi!B:D,3,0) -> NULL | BA30: =IF(AY30="eristav",AX30*AZ30," ") | BB30: =IF(AY30="eristav",AX30,0) -> 0 | BC30: =_xlfn.CONCAT(A30,"_",E30,"_",AT30,"_",AV30) -> S00002_53609056192_õppeaine46_44237 | BD30: =COUNTIF($BC$2:BC30, BC30) -> 1
A31: S00002 | B31: Anna | C31: Pärn | D31: Anna Pärn | E31: 53609056192 | F31: Naine | G31: 412 kutseõpe keskhariduse baasil | H31: Jah | I31: Ei | J31: Jah | K31: 44440 | L31: NULL | M31: 44504 | N31: Tugimeetmete rakendamine | O31: NULL | P31: 21sügis_TT | Q31: Akadeemilisel | R31: 44123 | S31: Päevaõpe | T31: Täiskoormus | U31: Tervishariduse keskus | V31: Tegevusterapeut | W31: 3311 | X31: 514 rakenduskõrgharidusõpe | Y31: NULL | Z31: 1 | AA31: Üliõpilaselt nõutakse õppekulude hüvitamist tasulisel õppekohal | AB31: eesti keel | AC31: 0.2 | AD31: Jah | AE31: liikumispuue | AF31: NULL | AG31: 184 | AH31: 33 | AI31: 4.9 | AJ31: 4.0 | AK31: 5.0 | AL31: 4.9 | AM31: 3 | AN31: 2 | AO31: 17 | AP31: 2 | AQ31: 48 | AR31: 9 | AS31: Arvestatud | AT31: õppeaine18 | AU31: õppeaine18 | AV31: 44814 | AW31: 4 | AX31: =VLOOKUP(dummy_data!$AU31,dummy_oppeained!B:C,2,0) -> 2 | AY31: =VLOOKUP(AT31,dummy_oppeained!B:D,3,0) -> mitteeristav | AZ31: =VLOOKUP(AS:AS,hinded_abi!B:D,3,0) -> NULL | BA31: =IF(AY31="eristav",AX31*AZ31," ") | BB31: =IF(AY31="eristav",AX31,0) -> 0 | BC31: =_xlfn.CONCAT(A31,"_",E31,"_",AT31,"_",AV31) -> S00002_53609056192_õppeaine18_44814 | BD31: =COUNTIF($BC$2:BC31, BC31) -> 1
A32: S00002 | B32: Anna | C32: Pärn | D32: Anna Pärn | E32: 53609056192 | F32: Naine | G32: 412 kutseõpe keskhariduse baasil | H32: Jah | I32: Ei | J32: Jah | K32: 44440 | L32: NULL | M32: 44504 | N32: Tugimeetmete rakendamine | O32: NULL | P32: 21sügis_TT | Q32: Akadeemilisel | R32: 44123 | S32: Päevaõpe | T32: Täiskoormus | U32: Tervishariduse keskus | V32: Tegevusterapeut | W32: 3311 | X32: 514 rakenduskõrgharidusõpe | Y32: NULL | Z32: 1 | AA32: Üliõpilaselt nõutakse õppekulude hüvitamist tasulisel õppekohal | AB32: eesti keel | AC32: 0.2 | AD32: Jah | AE32: liikumispuue | AF32: NULL | AG32: 184 | AH32: 33 | AI32: 4.9 | AJ32: 4.0 | AK32: 5.0 | AL32: 4.9 | AM32: 3 | AN32: 2 | AO32: 17 | AP32: 2 | AQ32: 48 | AR32: 9 | AS32: Mitteilmunud | AT32: õppeaine50 | AU32: õppeaine50 | AV32: 44602 | AW32: 4 | AX32: =VLOOKUP(dummy_data!$AU32,dummy_oppeained!B:C,2,0) -> 6 | AY32: =VLOOKUP(AT32,dummy_oppeained!B:D,3,0) -> eristav | AZ32: =VLOOKUP(AS:AS,hinded_abi!B:D,3,0) -> 0 | BA32: =IF(AY32="eristav",AX32*AZ32," ") -> 0 | BB32: =IF(AY32="eristav",AX32,0) -> 6 | BC32: =_xlfn.CONCAT(A32,"_",E32,"_",AT32,"_",AV32) -> S00002_53609056192_õppeaine50_44602 | BD32: =COUNTIF($BC$2:BC32, BC32) -> 1
A33: S00002 | B33: Anna | C33: Pärn | D33: Anna Pärn | E33: 53609056192 | F33: Naine | G33: 412 kutseõpe keskhariduse baasil | H33: Jah | I33: Ei | J33: Jah | K33: 44440 | L33: NULL | M33: 44504 | N33: Tugimeetmete rakendamine | O33: NULL | P33: 21sügis_TT | Q33: Akadeemilisel | R33: 44123 | S33: Päevaõpe | T33: Täiskoormus | U33: Tervishariduse keskus | V33: Tegevusterapeut | W33: 3311 | X33: 514 rakenduskõrgharidusõpe | Y33: NULL | Z33: 1 | AA33: Üliõpilaselt nõutakse õppekulude hüvitamist tasulisel õppekohal | AB33: eesti keel | AC33: 0.2 | AD33: Jah | AE33: liikumispuue | AF33: NULL | AG33: 184 | AH33: 33 | AI33: 4.9 | AJ33: 4.0 | AK33: 5.0 | AL33: 4.9 | AM33: 3 | AN33: 2 | AO33: 17 | AP33: 2 | AQ33: 48 | AR33: 9 | AS33: Suurepärane | AT33: õppeaine81 | AU33: õppeaine81 | AV33: 44814 | AW33: 4 | AX33: =VLOOKUP(dummy_data!$AU33,dummy_oppeained!B:C,2,0) -> 5 | AY33: =VLOOKUP(AT33,dummy_oppeained!B:D,3,0) -> eristav | AZ33: =VLOOKUP(AS:AS,hinded_abi!B:D,3,0) -> 5 | BA33: =IF(AY33="eristav",AX33*AZ33," ") -> 25 | BB33: =IF(AY33="eristav",AX33,0) -> 5 | BC33: =_xlfn.CONCAT(A33,"_",E33,"_",AT33,"_",AV33) -> S00002_53609056192_õppeaine81_44814 | BD33: =COUNTIF($BC$2:BC33, BC33) -> 1
A34: S00002 | B34: Anna | C34: Pärn | D34: Anna Pärn | E34: 53609056192 | F34: Naine | G34: 412 kutseõpe keskhariduse baasil | H34: Jah | I34: Ei | J34: Jah | K34: 44440 | L34: NULL | M34: 44504 | N34: Tugimeetmete rakendamine | O34: NULL | P34: 21sügis_TT | Q34: Akadeemilisel | R34: 44123 | S34: Päevaõpe | T34: Täiskoormus | U34: Tervishariduse keskus | V34: Tegevusterapeut | W34: 3311 | X34: 514 rakenduskõrgharidusõpe | Y34: NULL | Z34: 1 | AA34: Üliõpilaselt nõutakse õppekulude hüvitamist tasulisel õppekohal | AB34: eesti keel | AC34: 0.2 | AD34: Jah | AE34: liikumispuue | AF34: NULL | AG34: 184 | AH34: 33 | AI34: 4.9 | AJ34: 4.0 | AK34: 5.0 | AL34: 4.9 | AM34: 3 | AN34: 2 | AO34: 17 | AP34: 2 | AQ34: 48 | AR34: 9 | AS34: Arvestatud | AT34: õppeaine76 | AU34: õppeaine76 | AV34: 44967 | AW34: 4 | AX34: =VLOOKUP(dummy_data!$AU34,dummy_oppeained!B:C,2,0) -> 3 | AY34: =VLOOKUP(AT34,dummy_oppeained!B:D,3,0) -> mitteeristav | AZ34: =VLOOKUP(AS:AS,hinded_abi!B:D,3,0) -> NULL | BA34: =IF(AY34="eristav",AX34*AZ34," ") | BB34: =IF(AY34="eristav",AX34,0) -> 0 | BC34: =_xlfn.CONCAT(A34,"_",E34,"_",AT34,"_",AV34) -> S00002_53609056192_õppeaine76_44967 | BD34: =COUNTIF($BC$2:BC34, BC34) -> 1
A35: S00002 | B35: Anna | C35: Pärn | D35: Anna Pärn | E35: 53609056192 | F35: Naine | G35: 412 kutseõpe keskhariduse baasil | H35: Jah | I35: Ei | J35: Jah | K35: 44440 | L35: NULL | M35: 44504 | N35: Tugimeetmete rakendamine | O35: NULL | P35: 21sügis_TT | Q35: Akadeemilisel | R35: 44123 | S35: Päevaõpe | T35: Täiskoormus | U35: Tervishariduse keskus | V35: Tegevusterapeut | W35: 3311 | X35: 514 rakenduskõrgharidusõpe | Y35: NULL | Z35: 1 | AA35: Üliõpilaselt nõutakse õppekulude hüvitamist tasulisel õppekohal | AB35: eesti keel | AC35: 0.2 | AD35: Jah | AE35: liikumispuue | AF35: NULL | AG35: 184 | AH35: 33 | AI35: 4.9 | AJ35: 4.0 | AK35: 5.0 | AL35: 4.9 | AM35: 3 | AN35: 2 | AO35: 17 | AP35: 2 | AQ35: 48 | AR35: 9 | AS35: Hea | AT35: õppeaine67 | AU35: õppeaine67 | AV35: 44449 | AW35: 4 | AX35: =VLOOKUP(dummy_data!$AU35,dummy_oppeained!B:C,2,0) -> 5 | AY35: =VLOOKUP(AT35,dummy_oppeained!B:D,3,0) -> eristav | AZ35: =VLOOKUP(AS:AS,hinded_abi!B:D,3,0) -> 3 | BA35: =IF(AY35="eristav",AX35*AZ35," ") -> 15 | BB35: =IF(AY35="eristav",AX35,0) -> 5 | BC35: =_xlfn.CONCAT(A35,"_",E35,"_",AT35,"_",AV35) -> S00002_53609056192_õppeaine67_44449 | BD35: =COUNTIF($BC$2:BC35, BC35) -> 1
A36: S00002 | B36: Anna | C36: Pärn | D36: Anna Pärn | E36: 53609056192 | F36: Naine | G36: 412 kutseõpe keskhariduse baasil | H36: Jah | I36: Ei | J36: Jah | K36: 44440 | L36: NULL | M36: 44504 | N36: Tugimeetmete rakendamine | O36: NULL | P36: 21sügis_TT | Q36: Akadeemilisel | R36: 44123 | S36: Päevaõpe | T36: Täiskoormus | U36: Tervishariduse keskus | V36: Tegevusterapeut | W36: 3311 | X36: 514 rakenduskõrgharidusõpe | Y36: NULL | Z36: 1 | AA36: Üliõpilaselt nõutakse õppekulude hüvitamist tasulisel õppekohal | AB36: eesti keel | AC36: 0.2 | AD36: Jah | AE36: liikumispuue | AF36: NULL | AG36: 184 | AH36: 33 | AI36: 4.9 | AJ36: 4.0 | AK36: 5.0 | AL36: 4.9 | AM36: 3 | AN36: 2 | AO36: 17 | AP36: 2 | AQ36: 48 | AR36: 9 | AS36: Mitteilmunud | AT36: õppeaine7 | AU36: õppeaine7 | AV36: 44237 | AW36: 4 | AX36: =VLOOKUP(dummy_data!$AU36,dummy_oppeained!B:C,2,0) -> 3 | AY36: =VLOOKUP(AT36,dummy_oppeained!B:D,3,0) -> mitteeristav | AZ36: =VLOOKUP(AS:AS,hinded_abi!B:D,3,0) -> 0 | BA36: =IF(AY36="eristav",AX36*AZ36," ") | BB36: =IF(AY36="eristav",AX36,0) -> 0 | BC36: =_xlfn.CONCAT(A36,"_",E36,"_",AT36,"_",AV36) -> S00002_53609056192_õppeaine7_44237 | BD36: =COUNTIF($BC$2:BC36, BC36) -> 1
A37: S00002 | B37: Anna | C37: Pärn | D37: Anna Pärn | E37: 53609056192 | F37: Naine | G37: 412 kutseõpe keskhariduse baasil | H37: Jah | I37: Ei | J37: Jah | K37: 44440 | L37: NULL | M37: 44504 | N37: Tugimeetmete rakendamine | O37: NULL | P37: 21sügis_TT | Q37: Akadeemilisel | R37: 44123 | S37: Päevaõpe | T37: Täiskoormus | U37: Tervishariduse keskus | V37: Tegevusterapeut | W37: 3311 | X37: 514 rakenduskõrgharidusõpe | Y37: NULL | Z37: 1 | AA37: Üliõpilaselt nõutakse õppekulude hüvitamist tasulisel õppekohal | AB37: eesti keel | AC37: 0.2 | AD37: Jah | AE37: liikumispuue | AF37: NULL | AG37: 184 | AH37: 33 | AI37: 4.9 | AJ37: 4.0 | AK37: 5.0 | AL37: 4.9 | AM37: 3 | AN37: 2 | AO37: 17 | AP37: 2 | AQ37: 48 | AR37: 9 | AS37: Kasin | AT37: õppeaine36 | AU37: õppeaine36 | AV37: 44084 | AW37: 4 | AX37: =VLOOKUP(dummy_data!$AU37,dummy_oppeained!B:C,2,0) -> 6 | AY37: =VLOOKUP(AT37,dummy_oppeained!B:D,3,0) -> eristav | AZ37: =VLOOKUP(AS:AS,hinded_abi!B:D,3,0) -> 1 | BA37: =IF(AY37="eristav",AX37*AZ37," ") -> 6 | BB37: =IF(AY37="eristav",AX37,0) -> 6 | BC37: =_xlfn.CONCAT(A37,"_",E37,"_",AT37,"_",AV37) -> S00002_53609056192_õppeaine36_44084 | BD37: =COUNTIF($BC$2:BC37, BC37) -> 1
A38: S00002 | B38: Anna | C38: Pärn | D38: Anna Pärn | E38: 53609056192 | F38: Naine | G38: 412 kutseõpe keskhariduse baasil | H38: Jah | I38: Ei | J38: Jah | K38: 44440 | L38: NULL | M38: 44504 | N38: Tugimeetmete rakendamine | O38: NULL | P38: 21sügis_TT | Q38: Akadeemilisel | R38: 44123 | S38: Päevaõpe | T38: Täiskoormus | U38: Tervishariduse keskus | V38: Tegevusterapeut | W38: 3311 | X38: 514 rakenduskõrgharidusõpe | Y38: NULL | Z38: 1 | AA38: Üliõpilaselt nõutakse õppekulude hüvitamist tasulisel õppekohal | AB38: eesti keel | AC38: 0.2 | AD38: Jah | AE38: liikumispuue | AF38: NULL | AG38: 184 | AH38: 33 | AI38: 4.9 | AJ38: 4.0 | AK38: 5.0 | AL38: 4.9 | AM38: 3 | AN38: 2 | AO38: 17 | AP38: 2 | AQ38: 48 | AR38: 9 | AS38: Kasin | AT38: õppeaine38 | AU38: õppeaine38 | AV38: 44967 | AW38: 4 | AX38: =VLOOKUP(dummy_data!$AU38,dummy_oppeained!B:C,2,0) -> 9 | AY38: =VLOOKUP(AT38,dummy_oppeained!B:D,3,0) -> eristav | AZ38: =VLOOKUP(AS:AS,hinded_abi!B:D,3,0) -> 1 | BA38: =IF(AY38="eristav",AX38*AZ38," ") -> 9 | BB38: =IF(AY38="eristav",AX38,0) -> 9 | BC38: =_xlfn.CONCAT(A38,"_",E38,"_",AT38,"_",AV38) -> S00002_53609056192_õppeaine38_44967 | BD38: =COUNTIF($BC$2:BC38, BC38) -> 1
A39: S00002 | B39: Anna | C39: Pärn | D39: Anna Pärn | E39: 53609056192 | F39: Naine | G39: 412 kutseõpe keskhariduse baasil | H39: Jah | I39: Ei | J39: Jah | K39: 44440 | L39: NULL | M39: 44504 | N39: Tugimeetmete rakendamine | O39: NULL | P39: 21sügis_TT | Q39: Akadeemilisel | R39: 44123 | S39: Päevaõpe | T39: Täiskoormus | U39: Tervishariduse keskus | V39: Tegevusterapeut | W39: 3311 | X39: 514 rakenduskõrgharidusõpe | Y39: NULL | Z39: 1 | AA39: Üliõpilaselt nõutakse õppekulude hüvitamist tasulisel õppekohal | AB39: eesti keel | AC39: 0.2 | AD39: Jah | AE39: liikumispuue | AF39: NULL | AG39: 184 | AH39: 33 | AI39: 4.9 | AJ39: 4.0 | AK39: 5.0 | AL39: 4.9 | AM39: 3 | AN39: 2 | AO39: 17 | AP39: 2 | AQ39: 48 | AR39: 9 | AS39: Väga hea | AT39: õppeaine56 | AU39: õppeaine56 | AV39: 44237 | AW39: 4 | AX39: =VLOOKUP(dummy_data!$AU39,dummy_oppeained!B:C,2,0) -> 6 | AY39: =VLOOKUP(AT39,dummy_oppeained!B:D,3,0) -> eristav | AZ39: =VLOOKUP(AS:AS,hinded_abi!B:D,3,0) -> 4 | BA39: =IF(AY39="eristav",AX39*AZ39," ") -> 24 | BB39: =IF(AY39="eristav",AX39,0) -> 6 | BC39: =_xlfn.CONCAT(A39,"_",E39,"_",AT39,"_",AV39) -> S00002_53609056192_õppeaine56_44237 | BD39: =COUNTIF($BC$2:BC39, BC39) -> 1
... A64: S00002 | B64: Anna | C64: Pärn | D64: Anna Pärn | E64: 53609056192 | F64: Naine | G64: 412 kutseõpe keskhariduse baasil | H64: Jah | I64: Ei | J64: Jah | K64: 44440 | L64: NULL | M64: 44504 | N64: Tugimeetmete rakendamine | O64: NULL | P64: 21sügis_TT | Q64: Akadeemilisel | R64: 44123 | S64: Päevaõpe | T64: Täiskoormus | U64: Tervishariduse keskus | V64: Tegevusterapeut | W64: 3311 | X64: 514 rakenduskõrgharidusõpe | Y64: NULL | Z64: 4 | AA64: Üliõpilaselt nõutakse õppekulude hüvitamist tasulisel õppekohal | AB64: eesti keel | AC64: 0.2 | AD64: Jah | AE64: liikumispuue | AF64: NULL | AG64: 184 | AH64: 34 | AI64: 4.9 | AJ64: 3.9 | AK64: 5.0 | AL64: 3.7 | AM64: 3 | AN64: 1 | AO64: 17 | AP64: 9 | AQ64: 42 | AR64: 9 | AS64: Suurepärane | AT64: õppeaine70 | AU64: õppeaine70 | AV64: 45698 | AW64: 4 | AX64: =VLOOKUP(dummy_data!$AU64,dummy_oppeained!B:C,2,0) -> 6 | AY64: =VLOOKUP(AT64,dummy_oppeained!B:D,3,0) -> eristav | AZ64: =VLOOKUP(AS:AS,hinded_abi!B:D,3,0) -> 5 | BA64: =IF(AY64="eristav",AX64*AZ64," ") -> 30 | BB64: =IF(AY64="eristav",AX64,0) -> 6 | BC64: =_xlfn.CONCAT(A64,"_",E64,"_",AT64,"_",AV64) -> S00002_53609056192_õppeaine70_45698 | BD64: =COUNTIF($BC$2:BC64, BC64) -> 1
A65: S00003 | B65: Anna | C65: Mägi | D65: Anna Mägi | E65: 53105112627 | F65: Naine | G65: 411 kutsekeskharidusõpe | H65: Jah | I65: Ei | J65: Jah | K65: 44440 | L65: 45711 | M65: 44655 | N65: Eksmatrikuleerimine | O65: Õppetööle mitteilmumine | P65: 21sügis_HT | Q65: Katkestanud | R65: 45354 | S65: Päevaõpe | T65: Osakoormus | U65: Meditsiinitehnilise hariduse keskus | V65: Hambatehnik | W65: 80166 | X65: 514 rakenduskõrgharidusõpe | Y65: NULL | Z65: 1 | AA65: Üliõpilane ei hüvita õppekulusid: õpib täies mahus eestikeelsel õppekaval | AB65: eesti keel | AC65: 0.8 | AD65: Ei | AE65: NULL | AF65: ABC OÜ | AG65: 178 | AH65: 55 | AI65: 3.9 | AJ65: 4.4 | AK65: 4.2 | AL65: 3.9 | AM65: 5 | AN65: 2 | AO65: 2 | AP65: 5 | AQ65: 45 | AR65: 10 | AS65: Arvestatud | AT65: õppeaine90 | AU65: õppeaine90 | AV65: 44237 | AW65: 3.5 | AX65: =VLOOKUP(dummy_data!$AU65,dummy_oppeained!B:C,2,0) -> 3 | AY65: =VLOOKUP(AT65,dummy_oppeained!B:D,3,0) -> mitteeristav | AZ65: =VLOOKUP(AS:AS,hinded_abi!B:D,3,0) -> NULL | BA65: =IF(AY65="eristav",AX65*AZ65," ") | BB65: =IF(AY65="eristav",AX65,0) -> 0 | BC65: =_xlfn.CONCAT(A65,"_",E65,"_",AT65,"_",AV65) -> S00003_53105112627_õppeaine90_44237 | BD65: =COUNTIF($BC$2:BC65, BC65) -> 1
A66: S00003 | B66: Anna | C66: Mägi | D66: Anna Mägi | E66: 53105112627 | F66: Naine | G66: 411 kutsekeskharidusõpe | H66: Jah | I66: Ei | J66: Jah | K66: 44440 | L66: 45711 | M66: 44655 | N66: Eksmatrikuleerimine | O66: Õppetööle mitteilmumine | P66: 21sügis_HT | Q66: Katkestanud | R66: 45354 | S66: Päevaõpe | T66: Osakoormus | U66: Meditsiinitehnilise hariduse keskus | V66: Hambatehnik | W66: 80166 | X66: 514 rakenduskõrgharidusõpe | Y66: NULL | Z66: 1 | AA66: Üliõpilane ei hüvita õppekulusid: õpib täies mahus eestikeelsel õppekaval | AB66: eesti keel | AC66: 0.8 | AD66: Ei | AE66: NULL | AF66: ABC OÜ | AG66: 178 | AH66: 55 | AI66: 3.9 | AJ66: 4.4 | AK66: 4.2 | AL66: 3.9 | AM66: 5 | AN66: 2 | AO66: 2 | AP66: 5 | AQ66: 45 | AR66: 10 | AS66: Kasin | AT66: õppeaine97 | AU66: õppeaine97 | AV66: 45698 | AW66: 3.5 | AX66: =VLOOKUP(dummy_data!$AU66,dummy_oppeained!B:C,2,0) -> 6 | AY66: =VLOOKUP(AT66,dummy_oppeained!B:D,3,0) -> eristav | AZ66: =VLOOKUP(AS:AS,hinded_abi!B:D,3,0) -> 1 | BA66: =IF(AY66="eristav",AX66*AZ66," ") -> 6 | BB66: =IF(AY66="eristav",AX66,0) -> 6 | BC66: =_xlfn.CONCAT(A66,"_",E66,"_",AT66,"_",AV66) -> S00003_53105112627_õppeaine97_45698 | BD66: =COUNTIF($BC$2:BC66, BC66) -> 1
A67: S00003 | B67: Anna | C67: Mägi | D67: Anna Mägi | E67: 53105112627 | F67: Naine | G67: 411 kutsekeskharidusõpe | H67: Jah | I67: Ei | J67: Jah | K67: 44440 | L67: 45711 | M67: 44655 | N67: Eksmatrikuleerimine | O67: Õppetööle mitteilmumine | P67: 21sügis_HT | Q67: Katkestanud | R67: 45354 | S67: Päevaõpe | T67: Osakoormus | U67: Meditsiinitehnilise hariduse keskus | V67: Hambatehnik | W67: 80166 | X67: 514 rakenduskõrgharidusõpe | Y67: NULL | Z67: 1 | AA67: Üliõpilane ei hüvita õppekulusid: õpib täies mahus eestikeelsel õppekaval | AB67: eesti keel | AC67: 0.8 | AD67: Ei | AE67: NULL | AF67: ABC OÜ | AG67: 178 | AH67: 55 | AI67: 3.9 | AJ67: 4.4 | AK67: 4.2 | AL67: 3.9 | AM67: 5 | AN67: 2 | AO67: 2 | AP67: 5 | AQ67: 45 | AR67: 10 | AS67: Kasin | AT67: õppeaine65 | AU67: õppeaine65 | AV67: 45179 | AW67: 3.5 | AX67: =VLOOKUP(dummy_data!$AU67,dummy_oppeained!B:C,2,0) -> 8 | AY67: =VLOOKUP(AT67,dummy_oppeained!B:D,3,0) -> eristav | AZ67: =VLOOKUP(AS:AS,hinded_abi!B:D,3,0) -> 1 | BA67: =IF(AY67="eristav",AX67*AZ67," ") -> 8 | BB67: =IF(AY67="eristav",AX67,0) -> 8 | BC67: =_xlfn.CONCAT(A67,"_",E67,"_",AT67,"_",AV67) -> S00003_53105112627_õppeaine65_45179 | BD67: =COUNTIF($BC$2:BC67, BC67) -> 1
A68: S00003 | B68: Anna | C68: Mägi | D68: Anna Mägi | E68: 53105112627 | F68: Naine | G68: 411 kutsekeskharidusõpe | H68: Jah | I68: Ei | J68: Jah | K68: 44440 | L68: 45711 | M68: 44655 | N68: Eksmatrikuleerimine | O68: Õppetööle mitteilmumine | P68: 21sügis_HT | Q68: Katkestanud | R68: 45354 | S68: Päevaõpe | T68: Osakoormus | U68: Meditsiinitehnilise hariduse keskus | V68: Hambatehnik | W68: 80166 | X68: 514 rakenduskõrgharidusõpe | Y68: NULL | Z68: 1 | AA68: Üliõpilane ei hüvita õppekulusid: õpib täies mahus eestikeelsel õppekaval | AB68: eesti keel | AC68: 0.8 | AD68: Ei | AE68: NULL | AF68: ABC OÜ | AG68: 178 | AH68: 55 | AI68: 3.9 | AJ68: 4.4 | AK68: 4.2 | AL68: 3.9 | AM68: 5 | AN68: 2 | AO68: 2 | AP68: 5 | AQ68: 45 | AR68: 10 | AS68: Rahuldav | AT68: õppeaine96 | AU68: õppeaine96 | AV68: 45332 | AW68: 3.5 | AX68: =VLOOKUP(dummy_data!$AU68,dummy_oppeained!B:C,2,0) -> 5 | AY68: =VLOOKUP(AT68,dummy_oppeained!B:D,3,0) -> eristav | AZ68: =VLOOKUP(AS:AS,hinded_abi!B:D,3,0) -> 2 | BA68: =IF(AY68="eristav",AX68*AZ68," ") -> 10 | BB68: =IF(AY68="eristav",AX68,0) -> 5 | BC68: =_xlfn.CONCAT(A68,"_",E68,"_",AT68,"_",AV68) -> S00003_53105112627_õppeaine96_45332 | BD68: =COUNTIF($BC$2:BC68, BC68) -> 1
A69: S00003 | B69: Anna | C69: Mägi | D69: Anna Mägi | E69: 53105112627 | F69: Naine | G69: 411 kutsekeskharidusõpe | H69: Jah | I69: Ei | J69: Jah | K69: 44440 | L69: 45711 | M69: 44655 | N69: Eksmatrikuleerimine | O69: Õppetööle mitteilmumine | P69: 21sügis_HT | Q69: Katkestanud | R69: 45354 | S69: Päevaõpe | T69: Osakoormus | U69: Meditsiinitehnilise hariduse keskus | V69: Hambatehnik | W69: 80166 | X69: 514 rakenduskõrgharidusõpe | Y69: NULL | Z69: 1 | AA69: Üliõpilane ei hüvita õppekulusid: õpib täies mahus eestikeelsel õppekaval | AB69: eesti keel | AC69: 0.8 | AD69: Ei | AE69: NULL | AF69: ABC OÜ | AG69: 178 | AH69: 55 | AI69: 3.9 | AJ69: 4.4 | AK69: 4.2 | AL69: 3.9 | AM69: 5 | AN69: 2 | AO69: 2 | AP69: 5 | AQ69: 45 | AR69: 10 | AS69: Arvestatud | AT69: õppeaine85 | AU69: õppeaine85 | AV69: 44237 | AW69: 3.5 | AX69: =VLOOKUP(dummy_data!$AU69,dummy_oppeained!B:C,2,0) -> 3 | AY69: =VLOOKUP(AT69,dummy_oppeained!B:D,3,0) -> mitteeristav | AZ69: =VLOOKUP(AS:AS,hinded_abi!B:D,3,0) -> NULL | BA69: =IF(AY69="eristav",AX69*AZ69," ") | BB69: =IF(AY69="eristav",AX69,0) -> 0 | BC69: =_xlfn.CONCAT(A69,"_",E69,"_",AT69,"_",AV69) -> S00003_53105112627_õppeaine85_44237 | BD69: =COUNTIF($BC$2:BC69, BC69) -> 1
A70: S00003 | B70: Anna | C70: Mägi | D70: Anna Mägi | E70: 53105112627 | F70: Naine | G70: 411 kutsekeskharidusõpe | H70: Jah | I70: Ei | J70: Jah | K70: 44440 | L70: 45711 | M70: 44655 | N70: Eksmatrikuleerimine | O70: Õppetööle mitteilmumine | P70: 21sügis_HT | Q70: Katkestanud | R70: 45354 | S70: Päevaõpe | T70: Osakoormus | U70: Meditsiinitehnilise hariduse keskus | V70: Hambatehnik | W70: 80166 | X70: 514 rakenduskõrgharidusõpe | Y70: NULL | Z70: 2 | AA70: Üliõpilane ei hüvita õppekulusid: õpib täies mahus eestikeelsel õppekaval | AB70: eesti keel | AC70: 0.2 | AD70: Ei | AE70: NULL | AF70: ABC OÜ | AG70: 178 | AH70: 29 | AI70: 3.9 | AJ70: 3.8 | AK70: 4.2 | AL70: 3.7 | AM70: 5 | AN70: 2 | AO70: 2 | AP70: 2 | AQ70: 56 | AR70: 10 | AS70: Suurepärane | AT70: õppeaine54 | AU70: õppeaine54 | AV70: 44084 | AW70: 3.5 | AX70: =VLOOKUP(dummy_data!$AU70,dummy_oppeained!B:C,2,0) -> 5 | AY70: =VLOOKUP(AT70,dummy_oppeained!B:D,3,0) -> eristav | AZ70: =VLOOKUP(AS:AS,hinded_abi!B:D,3,0) -> 5 | BA70: =IF(AY70="eristav",AX70*AZ70," ") -> 25 | BB70: =IF(AY70="eristav",AX70,0) -> 5 | BC70: =_xlfn.CONCAT(A70,"_",E70,"_",AT70,"_",AV70) -> S00003_53105112627_õppeaine54_44084 | BD70: =COUNTIF($BC$2:BC70, BC70) -> 1
A71: S00003 | B71: Anna | C71: Mägi | D71: Anna Mägi | E71: 53105112627 | F71: Naine | G71: 411 kutsekeskharidusõpe | H71: Jah | I71: Ei | J71: Jah | K71: 44440 | L71: 45711 | M71: 44655 | N71: Eksmatrikuleerimine | O71: Õppetööle mitteilmumine | P71: 21sügis_HT | Q71: Katkestanud | R71: 45354 | S71: Päevaõpe | T71: Osakoormus | U71: Meditsiinitehnilise hariduse keskus | V71: Hambatehnik | W71: 80166 | X71: 514 rakenduskõrgharidusõpe | Y71: NULL | Z71: 2 | AA71: Üliõpilane ei hüvita õppekulusid: õpib täies mahus eestikeelsel õppekaval | AB71: eesti keel | AC71: 0.2 | AD71: Ei | AE71: NULL | AF71: ABC OÜ | AG71: 178 | AH71: 29 | AI71: 3.9 | AJ71: 3.8 | AK71: 4.2 | AL71: 3.7 | AM71: 5 | AN71: 2 | AO71: 2 | AP71: 2 | AQ71: 56 | AR71: 10 | AS71: Hea | AT71: õppeaine26 | AU71: õppeaine26 | AV71: 45545 | AW71: 3.5 | AX71: =VLOOKUP(dummy_data!$AU71,dummy_oppeained!B:C,2,0) -> 5 | AY71: =VLOOKUP(AT71,dummy_oppeained!B:D,3,0) -> eristav | AZ71: =VLOOKUP(AS:AS,hinded_abi!B:D,3,0) -> 3 | BA71: =IF(AY71="eristav",AX71*AZ71," ") -> 15 | BB71: =IF(AY71="eristav",AX71,0) -> 5 | BC71: =_xlfn.CONCAT(A71,"_",E71,"_",AT71,"_",AV71) -> S00003_53105112627_õppeaine26_45545 | BD71: =COUNTIF($BC$2:BC71, BC71) -> 1
A72: S00003 | B72: Anna | C72: Mägi | D72: Anna Mägi | E72: 53105112627 | F72: Naine | G72: 411 kutsekeskharidusõpe | H72: Jah | I72: Ei | J72: Jah | K72: 44440 | L72: 45711 | M72: 44655 | N72: Eksmatrikuleerimine | O72: Õppetööle mitteilmumine | P72: 21sügis_HT | Q72: Katkestanud | R72: 45354 | S72: Päevaõpe | T72: Osakoormus | U72: Meditsiinitehnilise hariduse keskus | V72: Hambatehnik | W72: 80166 | X72: 514 rakenduskõrgharidusõpe | Y72: NULL | Z72: 3 | AA72: Üliõpilane ei hüvita õppekulusid: õpib täies mahus eestikeelsel õppekaval | AB72: eesti keel | AC72: 0.5 | AD72: Ei | AE72: NULL | AF72: ABC OÜ | AG72: 178 | AH72: 50 | AI72: 3.9 | AJ72: 4.1 | AK72: 4.2 | AL72: 3.4 | AM72: 5 | AN72: 0 | AO72: 2 | AP72: 8 | AQ72: 24 | AR72: 10 | AS72: Mitteilmunud | AT72: õppeaine87 | AU72: õppeaine87 | AV72: 44449 | AW72: 3.5 | AX72: =VLOOKUP(dummy_data!$AU72,dummy_oppeained!B:C,2,0) -> 3 | AY72: =VLOOKUP(AT72,dummy_oppeained!B:D,3,0) -> mitteeristav | AZ72: =VLOOKUP(AS:AS,hinded_abi!B:D,3,0) -> 0 | BA72: =IF(AY72="eristav",AX72*AZ72," ") | BB72: =IF(AY72="eristav",AX72,0) -> 0 | BC72: =_xlfn.CONCAT(A72,"_",E72,"_",AT72,"_",AV72) -> S00003_53105112627_õppeaine87_44449 | BD72: =COUNTIF($BC$2:BC72, BC72) -> 1
A73: S00003 | B73: Anna | C73: Mägi | D73: Anna Mägi | E73: 53105112627 | F73: Naine | G73: 411 kutsekeskharidusõpe | H73: Jah | I73: Ei | J73: Jah | K73: 44440 | L73: 45711 | M73: 44655 | N73: Eksmatrikuleerimine | O73: Õppetööle mitteilmumine | P73: 21sügis_HT | Q73: Katkestanud | R73: 45354 | S73: Päevaõpe | T73: Osakoormus | U73: Meditsiinitehnilise hariduse keskus | V73: Hambatehnik | W73: 80166 | X73: 514 rakenduskõrgharidusõpe | Y73: NULL | Z73: 3 | AA73: Üliõpilane ei hüvita õppekulusid: õpib täies mahus eestikeelsel õppekaval | AB73: eesti keel | AC73: 0.5 | AD73: Ei | AE73: NULL | AF73: ABC OÜ | AG73: 178 | AH73: 50 | AI73: 3.9 | AJ73: 4.1 | AK73: 4.2 | AL73: 3.4 | AM73: 5 | AN73: 0 | AO73: 2 | AP73: 8 | AQ73: 24 | AR73: 10 | AS73: Arvestatud | AT73: õppeaine20 | AU73: õppeaine20 | AV73: 44967 | AW73: 3.5 | AX73: =VLOOKUP(dummy_data!$AU73,dummy_oppeained!B:C,2,0) -> 3 | AY73: =VLOOKUP(AT73,dummy_oppeained!B:D,3,0) -> mitteeristav | AZ73: =VLOOKUP(AS:AS,hinded_abi!B:D,3,0) -> NULL | BA73: =IF(AY73="eristav",AX73*AZ73," ") | BB73: =IF(AY73="eristav",AX73,0) -> 0 | BC73: =_xlfn.CONCAT(A73,"_",E73,"_",AT73,"_",AV73) -> S00003_53105112627_õppeaine20_44967 | BD73: =COUNTIF($BC$2:BC73, BC73) -> 1
A74: S00004 | B74: Laura | C74: Sepp | D74: Laura Sepp | E74: 53312199981 | F74: Naine | G74: 452 Viienda taseme kutseõppe esmaõpe | H74: Ei | I74: Ei | J74: Jah | K74: 44440 | L74: 44351 | M74: 45771 | N74: Eksmatrikuleerimine | O74: Tervislikel põhjustel | P74: 21sügis_Õde | Q74: Katkestanud | R74: 44203 | S74: Päevaõpe | T74: Osakoormus | U74: Õenduse õppetool | V74: Õde | W74: 1467 | X74: 514 rakenduskõrgharidusõpe | Z74: 1 | AA74: SF programmist „PRÕM“ rahastatav õppekoht: õpipoisiõpe | AB74: eesti keel | AC74: 0.7 | AD74: Jah | AE74: liikumispuue | AF74: DEF AS | AG74: 38 | AH74: 26 | AI74: 4.6 | AJ74: 4.5 | AK74: 4.5 | AL74: 4.8 | AM74: 3 | AN74: 1 | AO74: 3 | AP74: 5 | AQ74: 26 | AR74: 8 | AS74: Väga hea | AT74: õppeaine2 | AU74: õppeaine2 | AV74: 45179 | AW74: 3.5 | AX74: =VLOOKUP(dummy_data!$AU74,dummy_oppeained!B:C,2,0) -> 6 | AY74: =VLOOKUP(AT74,dummy_oppeained!B:D,3,0) -> eristav | AZ74: =VLOOKUP(AS:AS,hinded_abi!B:D,3,0) -> 4 | BA74: =IF(AY74="eristav",AX74*AZ74," ") -> 24 | BB74: =IF(AY74="eristav",AX74,0) -> 6 | BC74: =_xlfn.CONCAT(A74,"_",E74,"_",AT74,"_",AV74) -> S00004_53312199981_õppeaine2_45179 | BD74: =COUNTIF($BC$2:BC74, BC74) -> 1
A75: S00004 | B75: Laura | C75: Sepp | D75: Laura Sepp | E75: 53312199981 | F75: Naine | G75: 452 Viienda taseme kutseõppe esmaõpe | H75: Ei | I75: Ei | J75: Jah | K75: 44440 | L75: 44351 | M75: 45771 | N75: Eksmatrikuleerimine | O75: Tervislikel põhjustel | P75: 21sügis_Õde | Q75: Katkestanud | R75: 44203 | S75: Päevaõpe | T75: Osakoormus | U75: Õenduse õppetool | V75: Õde | W75: 1467 | X75: 514 rakenduskõrgharidusõpe | Z75: 1 | AA75: SF programmist „PRÕM“ rahastatav õppekoht: õpipoisiõpe | AB75: eesti keel | AC75: 0.7 | AD75: Jah | AE75: liikumispuue | AF75: DEF AS | AG75: 38 | AH75: 26 | AI75: 4.6 | AJ75: 4.5 | AK75: 4.5 | AL75: 4.8 | AM75: 3 | AN75: 1 | AO75: 3 | AP75: 5 | AQ75: 26 | AR75: 8 | AS75: Arvestatud | AT75: õppeaine57 | AU75: õppeaine57 | AV75: 44602 | AW75: 3.5 | AX75: =VLOOKUP(dummy_data!$AU75,dummy_oppeained!B:C,2,0) -> 3 | AY75: =VLOOKUP(AT75,dummy_oppeained!B:D,3,0) -> mitteeristav | AZ75: =VLOOKUP(AS:AS,hinded_abi!B:D,3,0) -> NULL | BA75: =IF(AY75="eristav",AX75*AZ75," ") | BB75: =IF(AY75="eristav",AX75,0) -> 0 | BC75: =_xlfn.CONCAT(A75,"_",E75,"_",AT75,"_",AV75) -> S00004_53312199981_õppeaine57_44602 | BD75: =COUNTIF($BC$2:BC75, BC75) -> 1
A76: S00004 | B76: Laura | C76: Sepp | D76: Laura Sepp | E76: 53312199981 | F76: Naine | G76: 452 Viienda taseme kutseõppe esmaõpe | H76: Ei | I76: Ei | J76: Jah | K76: 44440 | L76: 44351 | M76: 45771 | N76: Eksmatrikuleerimine | O76: Tervislikel põhjustel | P76: 21sügis_Õde | Q76: Katkestanud | R76: 44203 | S76: Päevaõpe | T76: Osakoormus | U76: Õenduse õppetool | V76: Õde | W76: 1467 | X76: 514 rakenduskõrgharidusõpe | Z76: 1 | AA76: SF programmist „PRÕM“ rahastatav õppekoht: õpipoisiõpe | AB76: eesti keel | AC76: 0.7 | AD76: Jah | AE76: liikumispuue | AF76: DEF AS | AG76: 38 | AH76: 26 | AI76: 4.6 | AJ76: 4.5 | AK76: 4.5 | AL76: 4.8 | AM76: 3 | AN76: 1 | AO76: 3 | AP76: 5 | AQ76: 26 | AR76: 8 | AS76: Arvestatud | AT76: õppeaine35 | AU76: õppeaine35 | AV76: 44237 | AW76: 3.5 | AX76: =VLOOKUP(dummy_data!$AU76,dummy_oppeained!B:C,2,0) -> 3 | AY76: =VLOOKUP(AT76,dummy_oppeained!B:D,3,0) -> mitteeristav | AZ76: =VLOOKUP(AS:AS,hinded_abi!B:D,3,0) -> NULL | BA76: =IF(AY76="eristav",AX76*AZ76," ") | BB76: =IF(AY76="eristav",AX76,0) -> 0 | BC76: =_xlfn.CONCAT(A76,"_",E76,"_",AT76,"_",AV76) -> S00004_53312199981_õppeaine35_44237 | BD76: =COUNTIF($BC$2:BC76, BC76) -> 1
A77: S00004 | B77: Laura | C77: Sepp | D77: Laura Sepp | E77: 53312199981 | F77: Naine | G77: 452 Viienda taseme kutseõppe esmaõpe | H77: Ei | I77: Ei | J77: Jah | K77: 44440 | L77: 44351 | M77: 45771 | N77: Eksmatrikuleerimine | O77: Tervislikel põhjustel | P77: 21sügis_Õde | Q77: Katkestanud | R77: 44203 | S77: Päevaõpe | T77: Osakoormus | U77: Õenduse õppetool | V77: Õde | W77: 1467 | X77: 514 rakenduskõrgharidusõpe | Z77: 2 | AA77: SF programmist „PRÕM“ rahastatav õppekoht: õpipoisiõpe | AB77: eesti keel | AC77: 0.6 | AD77: Jah | AE77: liikumispuue | AF77: DEF AS | AG77: 38 | AH77: 55 | AI77: 4.6 | AJ77: 4.4 | AK77: 4.5 | AL77: 3.1 | AM77: 3 | AN77: 0 | AO77: 3 | AP77: 1 | AQ77: 23 | AR77: 8 | AS77: Arvestatud | AT77: õppeaine6 | AU77: õppeaine6 | AV77: 44814 | AW77: 3.5 | AX77: =VLOOKUP(dummy_data!$AU77,dummy_oppeained!B:C,2,0) -> 3 | AY77: =VLOOKUP(AT77,dummy_oppeained!B:D,3,0) -> mitteeristav | AZ77: =VLOOKUP(AS:AS,hinded_abi!B:D,3,0) -> NULL | BA77: =IF(AY77="eristav",AX77*AZ77," ") | BB77: =IF(AY77="eristav",AX77,0) -> 0 | BC77: =_xlfn.CONCAT(A77,"_",E77,"_",AT77,"_",AV77) -> S00004_53312199981_õppeaine6_44814 | BD77: =COUNTIF($BC$2:BC77, BC77) -> 1
...

Sheet pivot_tava
A1: row_count | B1: 1 | H1: row_count | I1: 1
H2: matrikli_nr | I2: S00049
C3: Values
A4: Õppekava | B4: Õpperühm | C4: Count of matrikli_nr | D4: Sum of KKH | H4: Sum of KKH
A5: Assistant Pharmacist | B5: 20kevad_AP | C5: 71 | D5: 2.0068493 | H5: täisnimi | I5: Õppekava | J5: Õpperühm | K5: Keskmine kokku | L5: Õppeaine | M5: EAP | N5: hindamisviis | O5: Total
B6: 21sügis_AP | C6: 35 | D6: 2.1041667 | H6: Andres Gabriel Samuel Sepp | I6: Optometrist | J6: 22kevad_OP | K6: 4.7 | L6: õppeaine100 | M6: 6 | N6: eristav | O6: 1
B7: 22kevad_AP | C7: 46 | D7: 2.3917526 | L7: õppeaine12 | M7: 5 | N7: eristav | O7: 4
A8: Assistant Pharmacist Total | C8: 152 | D8: 2.147619 | L8: õppeaine16 | M8: 6 | N8: eristav | O8: 3
A9: Farmatseut | B9: 20kevad_FA | C9: 85 | D9: 2.1076923 | L9: õppeaine25 | M9: 5 | N9: eristav | O9: 3
B10: 21sügis_FA | C10: 134 | D10: 2.0147992 | L10: õppeaine36 | M10: 6 | N10: eristav | O10: 2
B11: 22kevad_FA | C11: 15 | D11: 2.4677419 | L11: õppeaine39 | M11: 5 | N11: eristav | O11: 0
B12: 23sügis_FA | C12: 7 | D12: 1.5277778 | L12: õppeaine69 | M12: 6 | N12: eristav | O12: 1
A13: Farmatseut Total | C13: 241 | D13: 2.0602679 | L13: õppeaine86 | M13: 6 | N13: eristav | O13: 0
A14: Hambatehnik | B14: 20kevad_HT | C14: 48 | D14: 1.7572816 | H14: Grand Total | O14: 1.7111111
B15: 20sügis_HT | C15: 33 | D15: 1.6126126
B16: 21sügis_HT | C16: 77 | D16: 2.1891892
A17: Hambatehnik Total | C17: 158 | D17: 1.9236111
A18: Optometrist | B18: 20kevad_OP | C18: 67 | D18: 1.3923077
B19: 21sügis_OP | C19: 52 | D19: 2.2727273
B20: 22kevad_OP | C20: 63 | D20: 2.1016043
A21: Optometrist Total | C21: 182 | D21: 1.8539326
A22: Tegevusterapeut | B22: 20kevad_TT | C22: 104 | D22: 2.3410256
B23: 20sügis_TT | C23: 16 | D23: 2.8636364
B24: 21sügis_TT | C24: 96 | D24: 1.8292079
B25: 22kevad_TT | C25: 39 | D25: 1.8278146
B26: 24sügis_TT | C26: 5 | D26: 2.9230769
A27: Tegevusterapeut Total | C27: 260 | D27: 2.0985222
A28: Tervisedendus | B28: 20kevad_TE | C28: 105 | D28: 2.184375
B29: 21sügis_TE | C29: 20 | D29: 2.5555556
B30: 22kevad_TE | C30: 30 | D30: 0.97894737
B31: 24sügis_TE | C31: 39 | D31: 0.9556962
A32: Tervisedendus Total | C32: 194 | D32: 1.7358491
A33: Terviseteadus | B33: 20kevad_Tteadus | C33: 94 | D33: 2.2131148
B34: 21sügis_Tteadus | C34: 14 | D34: 1.6734694
B35: 22kevad_Tteadus | C35: 61 | D35: 2.2279412
B36: 22sügis_Tteadus | C36: 22 | D36: 1.1445783
A37: Terviseteadus Total | C37: 191 | D37: 2.0688312
A38: Õde | B38: 20kevad_Õde | C38: 33 | D38: 3.226087
B39: 20sügis_Õde | C39: 38 | D39: 1.9701493
B40: 21kevad_Õde | C40: 5 | D40: 0.72727273
...

Sheet pivot_datamodel
